Workbook

Sheet Salary
B1: EMPLOYEE PAYROLL SHEET/ BẢNG LƯƠNG NHÂN VIÊN
B2: =[1]Overtime!A3 -> Jul 2026/ Tháng 07 năm 2026 (26 Jun 26 - 25 Jul 26)
B3: - Số công quy định trong tháng/ Standard working days: | J3: 26 | CJ3: Ngày công tháng trước | CK3: 27 | CV3: 46234 | CW3: 26 | EB3: 5 | EQ3: 2025
C4: 1 | D4: 2 | I4: 3 | J4: 4 | K4: 5 | L4: 6 | M4: 7 | N4: 8 | O4: 9 | P4: 10 | Q4: 11 | R4: 12 | S4: 13 | X4: 15 | Y4: 20 | Z4: 21 | AA4: 22 | AB4: 23 | AC4: 24 | AD4: 25 | AE4: 26 | AI4: 27 | AJ4: 28 | AK4: 30 | AL4: 31 | AM4: 32 | AN4: 33 | AO4: 19 | AX4: 34 | BE4: 35 | BF4: 36 | BG4: 37 | BH4: 38 | BI4: 39 | BJ4: 40 | BK4: 41 | BL4: 42 | BM4: 43 | BN4: 44 | BO4: 45 | BT4: 46 | BY4: 47 | BZ4: 48 | CA4: 49 | CG4: 50 | CH4: 51 | CI4: 52 | CJ4: 54 | CK4: 55 | CL4: 56 | CM4: 57 | CN4: 58 | CO4: 59 | EF4: 31 | EG4: 32 | EH4: 33 | EN4: 27 | EQ4: 37 | ES4: 50 | EU4: 50
B5: No./ STT | C5: Employee ID/ Mã NV | D5: Full name/ Họ tên | E5: Contract style/ Loại hợp đồng | F5: Accounting code | H5: Direct/ Indirect | I5: Line/ Chuyền | J5: Section/ Bộ phận | K5: Position/Chức vụ | L5: Salary for SI & HI Lương đóng BHXH,BHYT | M5: Salary for UI/ Lương đóng BHTN | N5: Salary in Labour Contract | Y5: Actual Salary in the Month | AK5: Overtime Salary/Lương ngoài giờ | AO5: Lucky money/ Lì xì 2026 | AP5: Tet bonus/ Thưởng Tết | AQ5: Special bonus/ Thưởng đặc biệt | AR5: Shift working support/ Tiền hỗ trợ làm ca | AS5: Children support/ Hỗ trợ con nhỏ | AT5: Process company supporting/ Hỗ trợ công ty gia công | AU5: Fire fighting training allowance/ Phụ cấp tham gia huấn luyện PCCC | AV5: 21,5% SI paid by Company during probation | AW5: Annual leave payment Thanh toán phép năm | AX5: Menstrual allowance Trợ cấp kinh nguyệt | AY5: Adjustment for previous month/ ĐC lương tháng trước | AZ5: KPIs bonus/ Thưởng đánh giá kết quả làm việc | BA5: Commuting supporting Hỗ trợ xăng xe | BE5: Gross salary/ Tổng tiền lương | BF5: Self reduction/ GT cá nhân | BG5: Dependant(s) Reduction/ GTGC | BH5: Deductions/Khác khoảng khấu trừ lương | BP5: Company/ Doanh nghiệp | BT5: Paid Lucky money/ Lì xì 2025 đã trả | BU5: YEP 2024 gifts paid/ Quà tiệc tất niên 2024 đã trả | BV5: Paid YEP 2026 support/ Hỗ trợ tiệc tất niên 2026 đã trả | BW5: Sunday meal support/ Tiền cơm chủ nhật | BX5: Salary advance/ Tạm ứng lương | BY5: Marriage gift/ Quà kết hôn | BZ5: PIT Finalization/ Quyết toán thuế | CA5: Severance allowance/ Trợ cấp thôi việc | CB5: Employee' contract compensation/ Tiền bồi thường hợp đồng của người lao động | CG5: Net Salary/ Lương thực nhận | CH5: Cost to company | CI5: Tet bonus estimation | CJ5: Ngày phép năm còn | CL5: Giờ kinh nguyệt | CN5: Chênh lệch lương tháng trước | CO5: Thanh lý hợp đồng | CP5: Nhập | CQ5: Nhập | CR5: Nhập | CS5: Nhập | CT5: Nhập | CU5: Nhập | CV5: Nhập | CW5: Nhập | EQ5: Dependant(s) Reduction/ GTGC
N6: Basic salary in labour contract/Lương trên HĐLĐ | O6: Technical allowance/Phụ cấp kỹ thuật | P6: Position allowance/Phụ cấp chức vụ | Q6: Accomodation Allowance/Phụ cấp nhà ở | R6: Commuting allowance Phụ cấp xăng xe | S6: Phone allowance Phụ cấp điện thoại | T6: Fire prevention and fighting allowance/Phụ cấp phòng cháy và chữa cháy: | U6: Safety and hygiene allowance/Phụ cấp an toàn vệ sinh viên | V6: Supporting stages allowance/Phụ cấp hỗ trợ công đoạn: | W6: Attendance incentive/Thưởng Chuyên cần | X6: Responsibility incentive Thưởng trách nhiệm | Y6: Working days/ Ngày công | Z6: Basic salary in labour contract/Lương cơ bản | AA6: Technical allowance/Phụ cấp kỹ thuật | AB6: Position allowance/ Phụ cấp chức vụ | AC6: Accomodation Allowance/ Phụ cấp nhà ở | AD6: Commuting bus Phụ cấp xăng xe | AE6: Phone Phụ cấp điện thoại | AF6: Fire prevention and fighting allowance/Phụ cấp phòng cháy và chữa cháy: | AG6: Safety and hygiene allowance/Phụ cấp an toàn vệ sinh viên | AH6: Supporting stages allowance/Phụ cấp hỗ trợ công đoạn: | AI6: Attendance incentive/ Thưởng Chuyên cần | AJ6: Responsibility incentive Thưởng trách nhiệm | AK6: Work hour/Giờ làm | AL6: 100% | AM6: Vượt 100% | AN6: Total/ Tổng tiền | BH6: Social Insurance/ BHXH(8%) | BI6: Health Insurance/ BHYT (1.5%) | BJ6: Unemployment Insurance/ BHTN (1%) | BK6: Union/ Công đoàn | BL6: Taxable income/ Thu nhập chịu thuế | BM6: Assessable income/Thu nhập tính thuế của NV | BN6: PIT/ Thuế thu nhập | BO6: Total deductions/ Tổng khấu trừ | BP6: Social Insurance/ BHXH (17,5%) | BQ6: Health Insurance/ BHYT (3%) | BR6: Unemployment Insurance/ BHTN (1%) | BS6: Union Fund/ KPCĐ (2%) | CJ6: Số ngày | CK6: Số tiền | CL6: Số giờ | CM6: Số tiền | CR6: 46218 | CV6: Chưa đóng BHXH | CW6: Chưa kí HĐ Chính thức đến ngày 25 | CX6: Chi khác ngoài bảng lương | DB6: Làm việc <5 ngày | DC6: Làm CN <=4h/ ngày (x) | DD6: Số ngày nghỉ bù làm CN | DE6: Đi trễ & về sớm | DF6: Tiền trừ đi trễ về sớm | DG6: Nghỉ không lương + Ốm + Con ốm | DH6: Tiền trừ không lương | DI6: Nghỉ Thai sản + Dưỡng sức | DJ6: Tiền CC tính theo thực tế | DK6: Tổng trừ CC | DL6: Ốm hưởng BHXH May | DM6: CO hưởng BHXH May | DN6: Tổng ngày nghỉ hưởng BHXH May | DO6: Tổng nghỉ KL May | DP6: Tổng nghỉ BHXH và KL May | DQ6: Tổng nghỉ ko đóng BH | DR6: Khám thai | DS6: Tiền CC khám thai | DT6: BHXH | DU6: BHYT | DV6: BHTN | DW6: Kinh phí CĐ | DX6: Tổng lương | DY6: Phụ cấp | DZ6: Thưởng | EA6: NKL | EB6: Check PIT Nhà ở | EF6: Check OT | EN6: Attendance incentive/ Thưởng Chuyên cần
D7: Tên | E7: Loại | H7: Phân loại | I7: Chuyền | J7: Bộ phận | K7: Chức vụ | L7: BHXH | M7: BHTN | N7: CB | O7: KT | P7: CV | Q7: NO | R7: XX | S7: ĐT | T7: PCCC | U7: ATVSTP | V7: HTCD | W7: CC | X7: TN | Y7: Ngày công | Z7: CB-TT | AA7: KT-TT | AB7: CV-TT | AC7: NO-TT | AD7: XX-TT | AE7: DT-TT | AF7: PCCC | AG7: ATVSTP | AH7: HTCD | AI7: CC-TT | AJ7: TN-TT | AK7: Giờ OT | AL7: 1 | AM7: Vuot 100% | AN7: OT | AO7: Lucky | AP7: Tet bonus | AQ7: Special bonus | AR7: Shift work | AS7: Child | AT7: Process | AV7: 0.215 | AW7: TL | AX7: KN | AY7: Đ/c lương tháng trc | AZ7: KPI | BA7: 100K XX | BE7: Tổng tiền lương | BF7: GT cá nhân | BG7: GTGC | BH7: BHXH 8% | BI7: BHYT 1,5% | BJ7: BHTN 1% | BK7: CĐ | BL7: TN chịu thuế | BM7: TN tính thuế | BN7: PIT | BO7: Tổng khấu trừ | BP7: BHXH 17.5% | BQ7: BHYT 3% | BR7: BHTN 1% | BS7: KPCD 2% | BT7: Lucky paid | BU7: YEP paid | BV7: YEP support paid | BW7: Sunday meal | BX7: TU | BY7: Quà KH | BZ7: QTT | CA7: TCTV | CB7: BTHD | CG7: Lương thực nhận | CH7: Cost to company | CI7: Tet bonus estimation | CJ7: Ngày phép năm còn | CK7: Tiền phép năm | CL7: Giờ KN | CM7: Tiền KN | CN7: Chênh lệch lương tháng trước | CO7: Thanh lý hợp đồng | CP7: Ngày vào làm | CQ7: Ngày kí HĐ | CR7: Nghĩ việc | CS7: Nghỉ thai sản | CT7: Thai sản đi làm lại | CU7: Tự ý bỏ việc | CV7: Xét tính 21.5% (x) - Chưa đóng BHXH | CW7: Thử việc (x) | CX7: Giỏ quà tết 02/02/2026 | CY7: Lì xì Tết 25/02/2026 | DT7: 0.175 | DU7: 0.03 | DV7: 0.01 | DW7: 0.02 | DX7: Tổng lương | DY7: Phụ cấp | DZ7: Thưởng | EA7: NKL | EB7: 15% TNCT | EC7: PC Nhà ở | ED7: Chênh lệch | EE7: Check 15% | EF7: Chịu thuế | EG7: Không chịu thuế | EH7: OT | EI7: Check OT Tax | EK7: OT150 | EL7: OT200 | EM7: GAP OT | EN7: CC-TT | EO7: Check | EP7: Check | EQ7: GTGC | ER7: Số người phụ thuộc
B8: I. Management
B9: II. Production | L9: =SUM(L10:L25) -> 107550000 | M9: =SUM(M10:M25) -> 107550000 | N9: =SUM(N10:N25) -> 83950000 | O9: =SUM(O10:O25) -> 7400000 | P9: =SUM(P10:P25) -> 0 | Q9: =SUM(Q10:Q25) -> 0 | R9: =SUM(R10:R25) -> 4800000 | S9: =SUM(S10:S25) -> 0 | ... EP9: =SUM(EP10:EP25) -> 0 | EQ9: 1315600000
B10: 1 | C10: TIQN-1457 | D10: Nguyễn Thị Thu Nhi | E10: =IF(CW10="x","Probation",IF(CR10>0,"Resigned - Official","Official")) -> Resigned - Official | F10: =IF(H10="management","6421.11",0) -> 0 | G10: Sewing | H10: Direct | I10: Line 11 | J10: Sewing | K10: Sewing worker | L10: =M10 -> 6800000 | M10: =N10+O10+P10+W10+X10+T10+U10+V10 -> 6800000 | N10: 5000000 | O10: 800000 | P10: 0 | Q10: 0 | R10: 300000 | S10: 0 | T10: 0 | U10: 0 | V10: 0 | W10: 1000000 | X10: 0 | Y10: =_xlfn.XLOOKUP(C10,[1]Timesheet!$B$9:$B$25,[1]Timesheet!$AO$9:$AO$25,0,,1) -> 7.9 | Z10: =ROUND(N10/$J$3*Y10,0) -> 1519231 | AA10: =ROUND(O10/$J$3*(Y10+_xlfn.XLOOKUP(C10,[1]Timesheet!B:B,[1]Timesheet!BS:BS,0)),0) -> 243077 | AB10: =ROUND(IF(Y10>=8,P10,(P10/$J$3)*(Y10+_xlfn.XLOOKUP(C10,[1]Timesheet!B:B,[1]Timesheet!BS:BS,0))),0) -> 0 | AC10: =ROUND(IF(Y10>=14,Q10,(Q10/2)),0) -> 0 | AD10: =IF(_xlfn.XLOOKUP(Salary!C10,[1]Bus!B:B,[1]Bus!G:G,"",,-1)=1,0,ROUND((R10/$J$3)*ROUND(Y10+_xlfn.XLOOKUP(C10,[1]Timesheet!B:B,[1]Timesheet!BS:BS,0,,-1),0),0)) -> 92308 | AE10: =IF(Y10>0,S10,0) -> 0 | AF10: =ROUND(IF(Y10>=8,T10,(T10/$J$3)*(Y10+_xlfn.XLOOKUP(C10,[1]Timesheet!B:B,[1]Timesheet!BS:BS,0))),0) -> 0 | AG10: =ROUND(IF(Y10>=8,U10,(U10/$J$3)*(Y10+_xlfn.XLOOKUP(C10,[1]Timesheet!B:B,[1]Timesheet!BS:BS,0))),0) -> 0 | AH10: =ROUND(IF(OR(CR10>0,Y10<8),(V10/$J$3)*(Y10+_xlfn.XLOOKUP(C10,[1]Timesheet!B:B,[1]Timesheet!BS:BS,0)),V10),0) -> 0 | AI10: =ROUND(IF(DAY(CR10)=26,IF(Y10=0,0,IF(W10=0,0,IF(OR(-(DK10)>DJ10,-(DK10)=DJ10),0,DJ10+DK10+DS10))),IF(CR10>0,0,IF(Y10=0,0,IF(W10=0,0,IF(OR(-(DK10)>DJ10,-(DK10)=DJ10),0,DJ10+DK10+DS10))))),0) -> 0 | AJ10: =IF(Y10>0,ROUND(IF(LEN(CR10)>2,(X10/$J$3)*(Y10+_xlfn.XLOOKUP(C10,[1]Timesheet!B:B,[1]Timesheet!BS:BS,0)),X10),0),0) -> 0 | AK10: =_xlfn.XLOOKUP(C10,[1]Overtime!$B$7:$B$557,[1]Overtime!$AN$7:$AN$557,0) -> 5.1 | AL10: =ROUND(((SUM(N10:P10)+SUM(T10:X10))/($J$3*8))*_xlfn.XLOOKUP(C10,[1]Overtime!$B$9:$B$557,[1]Overtime!$AU$9:$AU$557,0),0) -> 166731 | AM10: =ROUND(((SUM(N10:P10)+SUM(T10:X10))/($J$3*8))*_xlfn.XLOOKUP(C10,[1]Overtime!$B$9:$B$557,[1]Overtime!$AY$9:$AY$557,0),0) -> 83365 | AN10: =ROUND(AM10+AL10,0) -> 250096 | AR10: =ROUND(_xlfn.XLOOKUP(C10,[1]Timesheet!$B$9:$B$458,[1]Timesheet!$BQ$9:$BQ$458,,,-1)*SUM(Salary!N10:P10,Salary!T10:X10)*20%/Salary!$J$3,0) -> 0 | AS10: 0 | AT10: 0 | AV10: =IF(CV10="x",IF(IF(CR10>0,$CW$3-_xlfn.XLOOKUP(C10,[1]Timesheet!B:B,[1]Timesheet!BW:BW,0,,-1),$CW$3-_xlfn.XLOOKUP(C10,[1]Timesheet!B:B,[1]Timesheet!BW:BW,0,,-1)-$EB$3)<14,ROUND(L10*20.5%+M10*1%,0),0),0) -> 0 | AW10: =CK10 -> 654815 | AX10: =CM10 -> 343269 | AZ10: 0 | BE10: =ROUND(SUM(Z10:AJ10)+AN10+AX10+AT10+AO10+AR10+AS10+AW10+AY10+AV10+AP10+AU10+AQ10+AZ10+BA10,0) -> 3102796 | BF10: =IF(OR(CW10="x",CR10>0),0,15500000) -> 0 | BG10: 0 | BI10: =IF(CV10="x",0,ROUND(L10*1.5%,0)) -> 102000 | BJ10: =IF(CV10="x",0,ROUND(IF(BH10>0,M10*1%,0),0)) -> 0 | BK10: =IF(CV10="x",0,ROUND(IF(BH10>0,38948,0),0)) -> 0 | BL10: =ROUND(IF(AC10>0,IF(ROUND((BE10+CX10+CY10-AE10-AN10-AW10-AC10)*15%,0)>AC10,BE10+CX10+CY10-AE10-AN10-AW10,BE10+CX10+CY10-AE10-AN10-AW10-AC10+ROUND((BE10+CX10+CY10-AE10-AN10-AW10-AC10)*15%,0)),BE10+CX10+CY10-AE10-AN10-AW10),0) -> 2197885 | BM10: =IF(OR(CW10="x",CR10>0),BL10,IF(BL10-BF10-BG10-SUM(BH10:BJ10)>0,BL10-BF10-BG10-SUM(BH10:BJ10),0)) -> 2197885 | BN10: =IF(OR(CW10="x",CR10>0),ROUND(IF(BM10>4999999,BM10*10%,0),0),ROUND(IF(BM10>100000000,((BM10-100000000)*0.35+20500000),IF(AND(BM10>60000000,BM10<=100000000),((BM10-60000000)*0.3+8500000),IF(AND(BM10>30000000,BM10<=60000000),((BM10-30000000)*0.2+2500000),IF(AND(BM10>10000000,BM10<=30000000),((BM10-10000000)*0.1+500000),IF(BM10<0,0,(BM10*0.05)))))),0)) -> 0 | BO10: =SUM(BH10:BK10,BN10) -> 102000 | BP10: =IF(CV10="x",0,ROUND(IF(BH10>0,L10*17.5%,0),0)) -> 0 | BQ10: =IF(CV10="x",0,ROUND(IF(BI10>0,L10*3%,0),0)) -> 204000 | BR10: =IF(CV10="x",0,ROUND(IF(BJ10>0,M10*1%,0),0)) -> 0 | BS10: =IF(CV10="x",0,ROUND(IF(BK10>0,L10*2%,0),0)) -> 0 | BW10: 0 | CG10: =ROUND(BE10-BO10+BZ10-BT10-BU10-BX10-BV10+BW10+BY10+CA10-CB10,0) -> 3000796 | CH10: =CG10+BN10+SUM(BH10:BK10)+SUM(BP10:BS10) -> 3306796 | CI10: =IF(BH10=0,0,ROUND((SUM(N10:X10)-(R10+S10))/12,0)) -> 0 | CJ10: 2.6 | CK10: =ROUND((M10/$CK$3*CJ10),0) -> 654815 | CL10: =7*1.5 -> 10.5 | CM10: =ROUND((M10/$J$3/8*CL10),0) -> 343269 | CO10: =CK10+CM10 -> 998084 | CP10: 45786 | CQ10: 45816 | CR10: 46209 | CS10: 0 | CT10: 0 | DC10: =_xlfn.XLOOKUP(C10,[1]Overtime!$B$8:$B$2327,[1]Overtime!$BA$8:$BA$2327,"",,-1) -> 0 | DD10: =_xlfn.XLOOKUP(C10,[1]Timesheet!$B$9:$B$2328,[1]Timesheet!$BS$9:$BS$2328,0,,-1) -> 0 | DE10: =_xlfn.XLOOKUP(C10,[1]Timesheet!$B$7:$B$616,[1]Timesheet!$BK$7:$BK$616,0)+_xlfn.XLOOKUP(C10,[1]Timesheet!$B$7:$B$616,[1]Timesheet!$AV$7:$AV$616,0)-_xlfn.XLOOKUP(C10,[1]Timesheet!$B$7:$B$616,[1]Timesheet!$AX$7:$AX$616,0)+_xlfn.XLOOKUP(C10,[1]Timesheet!$B$7:$B$616,[1]Timesheet!$AW$7:$AW$616,0)-_xlfn.XLOOKUP(C10,[1]Timesheet!$B$7:$B$616,[1]Timesheet!$AY$7:$AY$616,0) -> 1 | DF10: =DE10*(-100000) -> -100000 | DG10: =_xlfn.XLOOKUP(C10,[1]Timesheet!$B$7:$B$616,[1]Timesheet!$BV$7:$BV$616,0)+_xlfn.XLOOKUP(C10,[1]Timesheet!$B$7:$B$616,[1]Timesheet!$AX$7:$AX$616,0)++_xlfn.XLOOKUP(C10,[1]Timesheet!$B$7:$B$616,[1]Timesheet!$AY$7:$AY$616,0) -> 0 | DH10: =IF(DG10>2,-1000000,IF(DG10=2,-500000,IF(DG10=1,-200000,0))) -> 0 | DI10: =_xlfn.XLOOKUP(C10,[1]Timesheet!$B$7:$B$616,[1]Timesheet!$AZ$7:$AZ$616,0)+_xlfn.XLOOKUP(C10,[1]Timesheet!$B$7:$B$616,[1]Timesheet!$BA$7:$BA$616,0) -> 0 | DJ10: =IF(CW10="x",IF((ROUND(Y10*W10/$J$3,0))<0,0,ROUND(Y10*W10/$J$3,0)),IF(OR(CR10>0,CS10>0,CT10>0),W10/$J$3*(Y10+_xlfn.XLOOKUP(C10,[1]Timesheet!B:B,[1]Timesheet!BS:BS,0,,-1)+_xlfn.XLOOKUP(C10,[1]Timesheet!B:B,[1]Timesheet!BU:BU,0,,-1)),IF(OR(DH10<0,DF10<0),IF(DI10>0,W10/$J$3*($J$3-DI10),W10),W10/$J$3*(Y10+_xlfn.XLOOKUP(C10,[1]Timesheet!B:B,[1]Timesheet!BS:BS,0,,-1)+_xlfn.XLOOKUP(C10,[1]Timesheet!B:B,[1]Timesheet!BU:BU,0,,-1))))) -> 303846.15 | DK10: =DF10+DH10 -> -100000 | DL10: =_xlfn.XLOOKUP(C10,[1]Timesheet!$B$7:$B$565,[1]Timesheet!$BB$7:$BB$565,0) -> 0 | DM10: =_xlfn.XLOOKUP(C10,[1]Timesheet!$B$7:$B$565,[1]Timesheet!$BC$7:$BC$565,0) -> 0 | DN10: =_xlfn.XLOOKUP(C10,[1]Timesheet!$B$7:$B$565,[1]Timesheet!$BF$7:$BF$565,0) -> 0 | DO10: =_xlfn.XLOOKUP(C10,[1]Timesheet!$B$7:$B$565,[1]Timesheet!$BJ$7:$BJ$565,0) -> 0 | DP10: =DN10+DO10 -> 0 | DQ10: =_xlfn.XLOOKUP(C10,[1]Timesheet!$B$7:$B$565,[1]Timesheet!$BT$7:$BT$565,0) -> 17 | DR10: =_xlfn.XLOOKUP(C10,[1]Timesheet!$B$7:$B$565,[1]Timesheet!$BM$7:$BM$565,0) -> 0 | DS10: =W10/$J$3*DR10 -> 0 | DT10: =ROUND(IF(BH10>0,L10*$DT$7,0),0) -> 0 | DU10: =ROUND(IF(BI10>0,L10*$DU$7,0),0) -> 204000 | DV10: =ROUND(IF(BJ10>0,M10*$DV$7,0),0) -> 0 | DW10: =ROUND(IF(BK10>0,L10*$DW$7,0),0) -> 0 | DX10: =SUM(N10:X10) -> 7100000 | DY10: =SUM(O10:S10) -> 1100000 | DZ10: =SUM(W10:X10) -> 1000000 | EA10: =_xlfn.XLOOKUP(C10,[1]Timesheet!$B$7:$B$565,[1]Timesheet!$BI$7:$BI$565,0) -> 0 | EB10: =IF(AC10>0,ROUND((BE10+CX10+CY10-AE10-AN10-AW10-AC10)*15%,0),0) -> 0 | EC10: =AC10 -> 0 | ED10: =EB10-EC10 -> 0 | EE10: =BE10+CX10+CY10-AE10-AN10-AW10-BL10 -> 0 | EF10: =ROUND((SUM(N10:P10)+W10+X10+T10+U10+V10)/($J$3*8)*_xlfn.XLOOKUP(C10,[1]Overtime!$B$9:$B$557,[1]Overtime!$AU$9:$AU$557,0),0) -> 166731 | EG10: =ROUND(((SUM(N10:P10)+W10+X10+T10+U10+V10)/($J$3*8))*_xlfn.XLOOKUP(C10,[1]Overtime!$B$9:$B$557,[1]Overtime!$AY$9:$AY$557,0),0) -> 83365 | EH10: =ROUND(EG10+EF10,0) -> 250096 | EI10: =AL10-EF10 -> 0 | EJ10: =AM10-EG10 -> 0 | EK10: =ROUND((SUM(N10:P10)+W10+X10+T10+U10+V10)/($J$3*8)*_xlfn.XLOOKUP(C10,[1]Overtime!$B$9:$B$557,[1]Overtime!$AO$9:$AO$557,0)*1.5,0) -> 250096 | EL10: =ROUND((SUM(N10:P10)+W10+X10+T10+U10+V10)/($J$3*8)*_xlfn.XLOOKUP(C10,[1]Overtime!$B$9:$B$557,[1]Overtime!$AP$9:$AP$557,0)*2,0) -> 0 | EM10: =AN10-EK10-EL10 -> 0 | EN10: =ROUND(Y10*W10/$J$3,0) -> 303846 | EO10: =DJ10-EN10 -> 0.15384615 | EP10: =IF(AI10=0,0,AI10-DK10-EN10) -> 0 | EQ10: 0 | ER10: =EQ10/4400000 -> 0
B11: =B10+1 -> 2 | C11: TIQN-1654 | D11: Đào Thị Bích Chương | E11: =IF(CW11="x","Probation",IF(CR11>0,"Resigned - Official","Official")) -> Resigned - Official | F11: =IF(H11="management","6421.11",0) -> 0 | G11: Preparation | H11: Indirect | I11: 2nd Process | J11: Preparation | K11: Supporting worker | L11: =M11 -> 6700000 | M11: =N11+O11+P11+W11+X11+T11+U11+V11 -> 6700000 | N11: 4900000 | O11: 800000 | P11: 0 | Q11: 0 | R11: 300000 | S11: 0 | T11: 0 | U11: 0 | V11: 0 | W11: 1000000 | X11: 0 | Y11: =_xlfn.XLOOKUP(C11,[1]Timesheet!$B$9:$B$25,[1]Timesheet!$AO$9:$AO$25,0,,1) -> 4 | Z11: =ROUND(N11/$J$3*Y11,0) -> 753846 | AA11: =ROUND(O11/$J$3*(Y11+_xlfn.XLOOKUP(C11,[1]Timesheet!B:B,[1]Timesheet!BS:BS,0)),0) -> 123077 | AB11: =ROUND(IF(Y11>=8,P11,(P11/$J$3)*(Y11+_xlfn.XLOOKUP(C11,[1]Timesheet!B:B,[1]Timesheet!BS:BS,0))),0) -> 0 | AC11: =ROUND(IF(Y11>=14,Q11,(Q11/2)),0) -> 0 | AD11: =IF(_xlfn.XLOOKUP(Salary!C11,[1]Bus!B:B,[1]Bus!G:G,"",,-1)=1,0,ROUND((R11/$J$3)*ROUND(Y11+_xlfn.XLOOKUP(C11,[1]Timesheet!B:B,[1]Timesheet!BS:BS,0,,-1),0),0)) -> 46154 | AE11: =IF(Y11>0,S11,0) -> 0 | AF11: =ROUND(IF(Y11>=8,T11,(T11/$J$3)*(Y11+_xlfn.XLOOKUP(C11,[1]Timesheet!B:B,[1]Timesheet!BS:BS,0))),0) -> 0 | AG11: =ROUND(IF(Y11>=8,U11,(U11/$J$3)*(Y11+_xlfn.XLOOKUP(C11,[1]Timesheet!B:B,[1]Timesheet!BS:BS,0))),0) -> 0 | AH11: =ROUND(IF(OR(CR11>0,Y11<8),(V11/$J$3)*(Y11+_xlfn.XLOOKUP(C11,[1]Timesheet!B:B,[1]Timesheet!BS:BS,0)),V11),0) -> 0 | AI11: =ROUND(IF(DAY(CR11)=26,IF(Y11=0,0,IF(W11=0,0,IF(OR(-(DK11)>DJ11,-(DK11)=DJ11),0,DJ11+DK11+DS11))),IF(CR11>0,0,IF(Y11=0,0,IF(W11=0,0,IF(OR(-(DK11)>DJ11,-(DK11)=DJ11),0,DJ11+DK11+DS11))))),0) -> 0 | AJ11: =IF(Y11>0,ROUND(IF(LEN(CR11)>2,(X11/$J$3)*(Y11+_xlfn.XLOOKUP(C11,[1]Timesheet!B:B,[1]Timesheet!BS:BS,0)),X11),0),0) -> 0 | AK11: =_xlfn.XLOOKUP(C11,[1]Overtime!$B$7:$B$557,[1]Overtime!$AN$7:$AN$557,0) -> 2 | AL11: =ROUND(((SUM(N11:P11)+SUM(T11:X11))/($J$3*8))*_xlfn.XLOOKUP(C11,[1]Overtime!$B$9:$B$557,[1]Overtime!$AU$9:$AU$557,0),0) -> 64423 | AM11: =ROUND(((SUM(N11:P11)+SUM(T11:X11))/($J$3*8))*_xlfn.XLOOKUP(C11,[1]Overtime!$B$9:$B$557,[1]Overtime!$AY$9:$AY$557,0),0) -> 32212 | AN11: =ROUND(AM11+AL11,0) -> 96635 | AR11: =ROUND(_xlfn.XLOOKUP(C11,[1]Timesheet!$B$9:$B$458,[1]Timesheet!$BQ$9:$BQ$458,,,-1)*SUM(Salary!N11:P11,Salary!T11:X11)*20%/Salary!$J$3,0) -> 0 | AS11: 0 | AT11: 0 | AV11: =IF(CV11="x",IF(IF(CR11>0,$CW$3-_xlfn.XLOOKUP(C11,[1]Timesheet!B:B,[1]Timesheet!BW:BW,0,,-1),$CW$3-_xlfn.XLOOKUP(C11,[1]Timesheet!B:B,[1]Timesheet!BW:BW,0,,-1)-$EB$3)<14,ROUND(L11*20.5%+M11*1%,0),0),0) -> 0 | AW11: =CK11 -> -99259 | AX11: =CM11 -> 289904 | AZ11: 0 | BE11: =ROUND(SUM(Z11:AJ11)+AN11+AX11+AT11+AO11+AR11+AS11+AW11+AY11+AV11+AP11+AU11+AQ11+AZ11+BA11,0) -> 1210357 | BF11: =IF(OR(CW11="x",CR11>0),0,15500000) -> 0 | BG11: 0 | BI11: =IF(CV11="x",0,ROUND(L11*1.5%,0)) -> 100500 | BJ11: =IF(CV11="x",0,ROUND(IF(BH11>0,M11*1%,0),0)) -> 0 | BK11: =IF(CV11="x",0,ROUND(IF(BH11>0,38948,0),0)) -> 0 | BL11: =ROUND(IF(AC11>0,IF(ROUND((BE11+CX11+CY11-AE11-AN11-AW11-AC11)*15%,0)>AC11,BE11+CX11+CY11-AE11-AN11-AW11,BE11+CX11+CY11-AE11-AN11-AW11-AC11+ROUND((BE11+CX11+CY11-AE11-AN11-AW11-AC11)*15%,0)),BE11+CX11+CY11-AE11-AN11-AW11),0) -> 1212981 | BM11: =IF(OR(CW11="x",CR11>0),BL11,IF(BL11-BF11-BG11-SUM(BH11:BJ11)>0,BL11-BF11-BG11-SUM(BH11:BJ11),0)) -> 1212981 | BN11: =IF(OR(CW11="x",CR11>0),ROUND(IF(BM11>4999999,BM11*10%,0),0),ROUND(IF(BM11>100000000,((BM11-100000000)*0.35+20500000),IF(AND(BM11>60000000,BM11<=100000000),((BM11-60000000)*0.3+8500000),IF(AND(BM11>30000000,BM11<=60000000),((BM11-30000000)*0.2+2500000),IF(AND(BM11>10000000,BM11<=30000000),((BM11-10000000)*0.1+500000),IF(BM11<0,0,(BM11*0.05)))))),0)) -> 0 | BO11: =SUM(BH11:BK11,BN11) -> 100500 | BP11: =IF(CV11="x",0,ROUND(IF(BH11>0,L11*17.5%,0),0)) -> 0 | BQ11: =IF(CV11="x",0,ROUND(IF(BI11>0,L11*3%,0),0)) -> 201000 | BR11: =IF(CV11="x",0,ROUND(IF(BJ11>0,M11*1%,0),0)) -> 0 | BS11: =IF(CV11="x",0,ROUND(IF(BK11>0,L11*2%,0),0)) -> 0 | BW11: 0 | CG11: =ROUND(BE11-BO11+BZ11-BT11-BU11-BX11-BV11+BW11+BY11+CA11-CB11,0) -> 1109857 | CH11: =CG11+BN11+SUM(BH11:BK11)+SUM(BP11:BS11) -> 1411357 | CI11: =IF(BH11=0,0,ROUND((SUM(N11:X11)-(R11+S11))/12,0)) -> 0 | CJ11: -0.4 | CK11: =ROUND((M11/$CK$3*CJ11),0) -> -99259 | CL11: =6*1.5 -> 9 | CM11: =ROUND((M11/$J$3/8*CL11),0) -> 289904 | CO11: =CK11+CM11 -> 190645 | CP11: 45926 | CQ11: 45956 | CR11: 46209 | CS11: 0 | CT11: 0 | DC11: =_xlfn.XLOOKUP(C11,[1]Overtime!$B$8:$B$2327,[1]Overtime!$BA$8:$BA$2327,"",,-1) -> 0 | DD11: =_xlfn.XLOOKUP(C11,[1]Timesheet!$B$9:$B$2328,[1]Timesheet!$BS$9:$BS$2328,0,,-1) -> 0 | DE11: =_xlfn.XLOOKUP(C11,[1]Timesheet!$B$7:$B$616,[1]Timesheet!$BK$7:$BK$616,0)+_xlfn.XLOOKUP(C11,[1]Timesheet!$B$7:$B$616,[1]Timesheet!$AV$7:$AV$616,0)-_xlfn.XLOOKUP(C11,[1]Timesheet!$B$7:$B$616,[1]Timesheet!$AX$7:$AX$616,0)+_xlfn.XLOOKUP(C11,[1]Timesheet!$B$7:$B$616,[1]Timesheet!$AW$7:$AW$616,0)-_xlfn.XLOOKUP(C11,[1]Timesheet!$B$7:$B$616,[1]Timesheet!$AY$7:$AY$616,0) -> 0 | DF11: =DE11*(-100000) -> 0 | DG11: =_xlfn.XLOOKUP(C11,[1]Timesheet!$B$7:$B$616,[1]Timesheet!$BV$7:$BV$616,0)+_xlfn.XLOOKUP(C11,[1]Timesheet!$B$7:$B$616,[1]Timesheet!$AX$7:$AX$616,0)++_xlfn.XLOOKUP(C11,[1]Timesheet!$B$7:$B$616,[1]Timesheet!$AY$7:$AY$616,0) -> 4 | DH11: =IF(DG11>2,-1000000,IF(DG11=2,-500000,IF(DG11=1,-200000,0))) -> -1000000 | DI11: =_xlfn.XLOOKUP(C11,[1]Timesheet!$B$7:$B$616,[1]Timesheet!$AZ$7:$AZ$616,0)+_xlfn.XLOOKUP(C11,[1]Timesheet!$B$7:$B$616,[1]Timesheet!$BA$7:$BA$616,0) -> 0 | DJ11: =IF(CW11="x",IF((ROUND(Y11*W11/$J$3,0))<0,0,ROUND(Y11*W11/$J$3,0)),IF(OR(CR11>0,CS11>0,CT11>0),W11/$J$3*(Y11+_xlfn.XLOOKUP(C11,[1]Timesheet!B:B,[1]Timesheet!BS:BS,0,,-1)+_xlfn.XLOOKUP(C11,[1]Timesheet!B:B,[1]Timesheet!BU:BU,0,,-1)),IF(OR(DH11<0,DF11<0),IF(DI11>0,W11/$J$3*($J$3-DI11),W11),W11/$J$3*(Y11+_xlfn.XLOOKUP(C11,[1]Timesheet!B:B,[1]Timesheet!BS:BS,0,,-1)+_xlfn.XLOOKUP(C11,[1]Timesheet!B:B,[1]Timesheet!BU:BU,0,,-1))))) -> 153846.15 | DK11: =DF11+DH11 -> -1000000 | DL11: =_xlfn.XLOOKUP(C11,[1]Timesheet!$B$7:$B$565,[1]Timesheet!$BB$7:$BB$565,0) -> 0 | DM11: =_xlfn.XLOOKUP(C11,[1]Timesheet!$B$7:$B$565,[1]Timesheet!$BC$7:$BC$565,0) -> 0 | DN11: =_xlfn.XLOOKUP(C11,[1]Timesheet!$B$7:$B$565,[1]Timesheet!$BF$7:$BF$565,0) -> 0 | DO11: =_xlfn.XLOOKUP(C11,[1]Timesheet!$B$7:$B$565,[1]Timesheet!$BJ$7:$BJ$565,0) -> 4 | DP11: =DN11+DO11 -> 4 | DQ11: =_xlfn.XLOOKUP(C11,[1]Timesheet!$B$7:$B$565,[1]Timesheet!$BT$7:$BT$565,0) -> 21 | DR11: =_xlfn.XLOOKUP(C11,[1]Timesheet!$B$7:$B$565,[1]Timesheet!$BM$7:$BM$565,0) -> 0 | DS11: =W11/$J$3*DR11 -> 0 | DT11: =ROUND(IF(BH11>0,L11*$DT$7,0),0) -> 0 | DU11: =ROUND(IF(BI11>0,L11*$DU$7,0),0) -> 201000 | DV11: =ROUND(IF(BJ11>0,M11*$DV$7,0),0) -> 0 | DW11: =ROUND(IF(BK11>0,L11*$DW$7,0),0) -> 0 | DX11: =SUM(N11:X11) -> 7000000 | DY11: =SUM(O11:S11) -> 1100000 | DZ11: =SUM(W11:X11) -> 1000000 | EA11: =_xlfn.XLOOKUP(C11,[1]Timesheet!$B$7:$B$565,[1]Timesheet!$BI$7:$BI$565,0) -> 4 | EB11: =IF(AC11>0,ROUND((BE11+CX11+CY11-AE11-AN11-AW11-AC11)*15%,0),0) -> 0 | EC11: =AC11 -> 0 | ED11: =EB11-EC11 -> 0 | EE11: =BE11+CX11+CY11-AE11-AN11-AW11-BL11 -> 0 | EF11: =ROUND((SUM(N11:P11)+W11+X11+T11+U11+V11)/($J$3*8)*_xlfn.XLOOKUP(C11,[1]Overtime!$B$9:$B$557,[1]Overtime!$AU$9:$AU$557,0),0) -> 64423 | EG11: =ROUND(((SUM(N11:P11)+W11+X11+T11+U11+V11)/($J$3*8))*_xlfn.XLOOKUP(C11,[1]Overtime!$B$9:$B$557,[1]Overtime!$AY$9:$AY$557,0),0) -> 32212 | EH11: =ROUND(EG11+EF11,0) -> 96635 | EI11: =AL11-EF11 -> 0 | EJ11: =AM11-EG11 -> 0 | EK11: =ROUND((SUM(N11:P11)+W11+X11+T11+U11+V11)/($J$3*8)*_xlfn.XLOOKUP(C11,[1]Overtime!$B$9:$B$557,[1]Overtime!$AO$9:$AO$557,0)*1.5,0) -> 96635 | EL11: =ROUND((SUM(N11:P11)+W11+X11+T11+U11+V11)/($J$3*8)*_xlfn.XLOOKUP(C11,[1]Overtime!$B$9:$B$557,[1]Overtime!$AP$9:$AP$557,0)*2,0) -> 0 | EM11: =AN11-EK11-EL11 -> 0 | EN11: =ROUND(Y11*W11/$J$3,0) -> 153846 | EO11: =DJ11-EN11 -> 0.15384615 | EP11: =IF(AI11=0,0,AI11-DK11-EN11) -> 0 | EQ11: 0 | ER11: =EQ11/4400000 -> 0
B12: =B11+1 -> 3 | C12: TIQN-1663 | D12: Nguyễn Thị Hương | E12: =IF(CW12="x","Probation",IF(CR12>0,"Resigned - Official","Official")) -> Resigned - Official | F12: =IF(H12="management","6421.11",0) -> 0 | G12: Sewing | H12: Direct | I12: Line 15 | J12: Sewing | K12: Sewing worker | L12: =M12 -> 6500000 | M12: =N12+O12+P12+W12+X12+T12+U12+V12 -> 6500000 | N12: 4700000 | O12: 800000 | P12: 0 | Q12: 0 | R12: 300000 | S12: 0 | T12: 0 | U12: 0 | V12: 0 | W12: 1000000 | X12: 0 | Y12: =_xlfn.XLOOKUP(C12,[1]Timesheet!$B$9:$B$25,[1]Timesheet!$AO$9:$AO$25,0,,1) -> 0 | Z12: =ROUND(N12/$J$3*Y12,0) -> 0 | AA12: =ROUND(O12/$J$3*(Y12+_xlfn.XLOOKUP(C12,[1]Timesheet!B:B,[1]Timesheet!BS:BS,0)),0) -> 0 | AB12: =ROUND(IF(Y12>=8,P12,(P12/$J$3)*(Y12+_xlfn.XLOOKUP(C12,[1]Timesheet!B:B,[1]Timesheet!BS:BS,0))),0) -> 0 | AC12: =ROUND(IF(Y12>=14,Q12,(Q12/2)),0) -> 0 | AD12: =IF(_xlfn.XLOOKUP(Salary!C12,[1]Bus!B:B,[1]Bus!G:G,"",,-1)=1,0,ROUND((R12/$J$3)*ROUND(Y12+_xlfn.XLOOKUP(C12,[1]Timesheet!B:B,[1]Timesheet!BS:BS,0,,-1),0),0)) -> 0 | AE12: =IF(Y12>0,S12,0) -> 0 | AF12: =ROUND(IF(Y12>=8,T12,(T12/$J$3)*(Y12+_xlfn.XLOOKUP(C12,[1]Timesheet!B:B,[1]Timesheet!BS:BS,0))),0) -> 0 | AG12: =ROUND(IF(Y12>=8,U12,(U12/$J$3)*(Y12+_xlfn.XLOOKUP(C12,[1]Timesheet!B:B,[1]Timesheet!BS:BS,0))),0) -> 0 | AH12: =ROUND(IF(OR(CR12>0,Y12<8),(V12/$J$3)*(Y12+_xlfn.XLOOKUP(C12,[1]Timesheet!B:B,[1]Timesheet!BS:BS,0)),V12),0) -> 0 | AI12: =ROUND(IF(DAY(CR12)=26,IF(Y12=0,0,IF(W12=0,0,IF(OR(-(DK12)>DJ12,-(DK12)=DJ12),0,DJ12+DK12+DS12))),IF(CR12>0,0,IF(Y12=0,0,IF(W12=0,0,IF(OR(-(DK12)>DJ12,-(DK12)=DJ12),0,DJ12+DK12+DS12))))),0) -> 0 | AJ12: =IF(Y12>0,ROUND(IF(LEN(CR12)>2,(X12/$J$3)*(Y12+_xlfn.XLOOKUP(C12,[1]Timesheet!B:B,[1]Timesheet!BS:BS,0)),X12),0),0) -> 0 | AK12: =_xlfn.XLOOKUP(C12,[1]Overtime!$B$7:$B$557,[1]Overtime!$AN$7:$AN$557,0) -> 0 | AL12: =ROUND(((SUM(N12:P12)+SUM(T12:X12))/($J$3*8))*_xlfn.XLOOKUP(C12,[1]Overtime!$B$9:$B$557,[1]Overtime!$AU$9:$AU$557,0),0) -> 0 | AM12: =ROUND(((SUM(N12:P12)+SUM(T12:X12))/($J$3*8))*_xlfn.XLOOKUP(C12,[1]Overtime!$B$9:$B$557,[1]Overtime!$AY$9:$AY$557,0),0) -> 0 | AN12: =ROUND(AM12+AL12,0) -> 0 | AR12: =ROUND(_xlfn.XLOOKUP(C12,[1]Timesheet!$B$9:$B$458,[1]Timesheet!$BQ$9:$BQ$458,,,-1)*SUM(Salary!N12:P12,Salary!T12:X12)*20%/Salary!$J$3,0) -> 0 | AS12: 0 | AT12: 0 | AV12: =IF(CV12="x",IF(IF(CR12>0,$CW$3-_xlfn.XLOOKUP(C12,[1]Timesheet!B:B,[1]Timesheet!BW:BW,0,,-1),$CW$3-_xlfn.XLOOKUP(C12,[1]Timesheet!B:B,[1]Timesheet!BW:BW,0,,-1)-$EB$3)<14,ROUND(L12*20.5%+M12*1%,0),0),0) -> 0 | AW12: =CK12 -> 264815 | AX12: =CM12 -> 281250 | AZ12: 0 | BE12: =ROUND(SUM(Z12:AJ12)+AN12+AX12+AT12+AO12+AR12+AS12+AW12+AY12+AV12+AP12+AU12+AQ12+AZ12+BA12,0) -> 546065 | BF12: =IF(OR(CW12="x",CR12>0),0,15500000) -> 0 | BG12: 0 | BJ12: =IF(CV12="x",0,ROUND(IF(BH12>0,M12*1%,0),0)) -> 0 | BK12: =IF(CV12="x",0,ROUND(IF(BH12>0,38948,0),0)) -> 0 | BL12: =ROUND(IF(AC12>0,IF(ROUND((BE12+CX12+CY12-AE12-AN12-AW12-AC12)*15%,0)>AC12,BE12+CX12+CY12-AE12-AN12-AW12,BE12+CX12+CY12-AE12-AN12-AW12-AC12+ROUND((BE12+CX12+CY12-AE12-AN12-AW12-AC12)*15%,0)),BE12+CX12+CY12-AE12-AN12-AW12),0) -> 281250 | BM12: =IF(OR(CW12="x",CR12>0),BL12,IF(BL12-BF12-BG12-SUM(BH12:BJ12)>0,BL12-BF12-BG12-SUM(BH12:BJ12),0)) -> 281250 | BN12: =IF(OR(CW12="x",CR12>0),ROUND(IF(BM12>4999999,BM12*10%,0),0),ROUND(IF(BM12>100000000,((BM12-100000000)*0.35+20500000),IF(AND(BM12>60000000,BM12<=100000000),((BM12-60000000)*0.3+8500000),IF(AND(BM12>30000000,BM12<=60000000),((BM12-30000000)*0.2+2500000),IF(AND(BM12>10000000,BM12<=30000000),((BM12-10000000)*0.1+500000),IF(BM12<0,0,(BM12*0.05)))))),0)) -> 0 | BO12: =SUM(BH12:BK12,BN12) -> 0 | BP12: =IF(CV12="x",0,ROUND(IF(BH12>0,L12*17.5%,0),0)) -> 0 | BQ12: =IF(CV12="x",0,ROUND(IF(BI12>0,L12*3%,0),0)) -> 0 | BR12: =IF(CV12="x",0,ROUND(IF(BJ12>0,M12*1%,0),0)) -> 0 | BS12: =IF(CV12="x",0,ROUND(IF(BK12>0,L12*2%,0),0)) -> 0 | BW12: 0 | CB12: 546065 | CG12: =ROUND(BE12-BO12+BZ12-BT12-BU12-BX12-BV12+BW12+BY12+CA12-CB12,0) -> 0 | CH12: =CG12+BN12+SUM(BH12:BK12)+SUM(BP12:BS12) -> 0 | CI12: =IF(BH12=0,0,ROUND((SUM(N12:X12)-(R12+S12))/12,0)) -> 0 | CJ12: 1.1 | CK12: =ROUND((M12/$CK$3*CJ12),0) -> 264815 | CL12: =6*1.5 -> 9 | CM12: =ROUND((M12/$J$3/8*CL12),0) -> 281250 | CO12: =CK12+CM12 -> 546065 | CP12: 45930 | CQ12: 45960 | CR12: 46207 | CS12: 0 | CT12: 0 | CU12: x | DC12: =_xlfn.XLOOKUP(C12,[1]Overtime!$B$8:$B$2327,[1]Overtime!$BA$8:$BA$2327,"",,-1) -> 0 | DD12: =_xlfn.XLOOKUP(C12,[1]Timesheet!$B$9:$B$2328,[1]Timesheet!$BS$9:$BS$2328,0,,-1) -> 0 | DE12: =_xlfn.XLOOKUP(C12,[1]Timesheet!$B$7:$B$616,[1]Timesheet!$BK$7:$BK$616,0)+_xlfn.XLOOKUP(C12,[1]Timesheet!$B$7:$B$616,[1]Timesheet!$AV$7:$AV$616,0)-_xlfn.XLOOKUP(C12,[1]Timesheet!$B$7:$B$616,[1]Timesheet!$AX$7:$AX$616,0)+_xlfn.XLOOKUP(C12,[1]Timesheet!$B$7:$B$616,[1]Timesheet!$AW$7:$AW$616,0)-_xlfn.XLOOKUP(C12,[1]Timesheet!$B$7:$B$616,[1]Timesheet!$AY$7:$AY$616,0) -> 0 | DF12: =DE12*(-100000) -> 0 | DG12: =_xlfn.XLOOKUP(C12,[1]Timesheet!$B$7:$B$616,[1]Timesheet!$BV$7:$BV$616,0)+_xlfn.XLOOKUP(C12,[1]Timesheet!$B$7:$B$616,[1]Timesheet!$AX$7:$AX$616,0)++_xlfn.XLOOKUP(C12,[1]Timesheet!$B$7:$B$616,[1]Timesheet!$AY$7:$AY$616,0) -> 7 | DH12: =IF(DG12>2,-1000000,IF(DG12=2,-500000,IF(DG12=1,-200000,0))) -> -1000000 | DI12: =_xlfn.XLOOKUP(C12,[1]Timesheet!$B$7:$B$616,[1]Timesheet!$AZ$7:$AZ$616,0)+_xlfn.XLOOKUP(C12,[1]Timesheet!$B$7:$B$616,[1]Timesheet!$BA$7:$BA$616,0) -> 0 | DJ12: =IF(CW12="x",IF((ROUND(Y12*W12/$J$3,0))<0,0,ROUND(Y12*W12/$J$3,0)),IF(OR(CR12>0,CS12>0,CT12>0),W12/$J$3*(Y12+_xlfn.XLOOKUP(C12,[1]Timesheet!B:B,[1]Timesheet!BS:BS,0,,-1)+_xlfn.XLOOKUP(C12,[1]Timesheet!B:B,[1]Timesheet!BU:BU,0,,-1)),IF(OR(DH12<0,DF12<0),IF(DI12>0,W12/$J$3*($J$3-DI12),W12),W12/$J$3*(Y12+_xlfn.XLOOKUP(C12,[1]Timesheet!B:B,[1]Timesheet!BS:BS,0,,-1)+_xlfn.XLOOKUP(C12,[1]Timesheet!B:B,[1]Timesheet!BU:BU,0,,-1))))) -> 0 | DK12: =DF12+DH12 -> -1000000 | DL12: =_xlfn.XLOOKUP(C12,[1]Timesheet!$B$7:$B$565,[1]Timesheet!$BB$7:$BB$565,0) -> 0 | DM12: =_xlfn.XLOOKUP(C12,[1]Timesheet!$B$7:$B$565,[1]Timesheet!$BC$7:$BC$565,0) -> 0 | DN12: =_xlfn.XLOOKUP(C12,[1]Timesheet!$B$7:$B$565,[1]Timesheet!$BF$7:$BF$565,0) -> 0 | DO12: =_xlfn.XLOOKUP(C12,[1]Timesheet!$B$7:$B$565,[1]Timesheet!$BJ$7:$BJ$565,0) -> 3 | DP12: =DN12+DO12 -> 3 | DQ12: =_xlfn.XLOOKUP(C12,[1]Timesheet!$B$7:$B$565,[1]Timesheet!$BT$7:$BT$565,0) -> 21 | DR12: =_xlfn.XLOOKUP(C12,[1]Timesheet!$B$7:$B$565,[1]Timesheet!$BM$7:$BM$565,0) -> 0 | DS12: =W12/$J$3*DR12 -> 0 | DT12: =ROUND(IF(BH12>0,L12*$DT$7,0),0) -> 0 | DU12: =ROUND(IF(BI12>0,L12*$DU$7,0),0) -> 0 | DV12: =ROUND(IF(BJ12>0,M12*$DV$7,0),0) -> 0 | DW12: =ROUND(IF(BK12>0,L12*$DW$7,0),0) -> 0 | DX12: =SUM(N12:X12) -> 6800000 | DY12: =SUM(O12:S12) -> 1100000 | DZ12: =SUM(W12:X12) -> 1000000 | EA12: =_xlfn.XLOOKUP(C12,[1]Timesheet!$B$7:$B$565,[1]Timesheet!$BI$7:$BI$565,0) -> 7 | EB12: =IF(AC12>0,ROUND((BE12+CX12+CY12-AE12-AN12-AW12-AC12)*15%,0),0) -> 0 | EC12: =AC12 -> 0 | ED12: =EB12-EC12 -> 0 | EE12: =BE12+CX12+CY12-AE12-AN12-AW12-BL12 -> 0 | EF12: =ROUND((SUM(N12:P12)+W12+X12+T12+U12+V12)/($J$3*8)*_xlfn.XLOOKUP(C12,[1]Overtime!$B$9:$B$557,[1]Overtime!$AU$9:$AU$557,0),0) -> 0 | EG12: =ROUND(((SUM(N12:P12)+W12+X12+T12+U12+V12)/($J$3*8))*_xlfn.XLOOKUP(C12,[1]Overtime!$B$9:$B$557,[1]Overtime!$AY$9:$AY$557,0),0) -> 0 | EH12: =ROUND(EG12+EF12,0) -> 0 | EI12: =AL12-EF12 -> 0 | EJ12: =AM12-EG12 -> 0 | EK12: =ROUND((SUM(N12:P12)+W12+X12+T12+U12+V12)/($J$3*8)*_xlfn.XLOOKUP(C12,[1]Overtime!$B$9:$B$557,[1]Overtime!$AO$9:$AO$557,0)*1.5,0) -> 0 | EL12: =ROUND((SUM(N12:P12)+W12+X12+T12+U12+V12)/($J$3*8)*_xlfn.XLOOKUP(C12,[1]Overtime!$B$9:$B$557,[1]Overtime!$AP$9:$AP$557,0)*2,0) -> 0 | EM12: =AN12-EK12-EL12 -> 0 | EN12: =ROUND(Y12*W12/$J$3,0) -> 0 | EO12: =DJ12-EN12 -> 0 | EP12: =IF(AI12=0,0,AI12-DK12-EN12) -> 0 | EQ12: 0 | ER12: =EQ12/4400000 -> 0
B13: =B12+1 -> 4 | C13: TIQN-2062 | D13: Mai Thị Tú Nhi | E13: =IF(CW13="x","Probation",IF(CR13>0,"Resigned - Official","Official")) -> Resigned - Official | F13: =IF(H13="management","6421.11",0) -> 0 | G13: Sewing | H13: Direct | I13: Line 02 | J13: Sewing | K13: Sewing worker | L13: =M13 -> 6500000 | M13: =N13+O13+P13+W13+X13+T13+U13+V13 -> 6500000 | N13: 5200000 | O13: 300000 | P13: 0 | Q13: 0 | R13: 300000 | S13: 0 | T13: 0 | U13: 0 | V13: 0 | W13: 1000000 | X13: 0 | Y13: =_xlfn.XLOOKUP(C13,[1]Timesheet!$B$9:$B$25,[1]Timesheet!$AO$9:$AO$25,0,,1) -> 0 | Z13: =ROUND(N13/$J$3*Y13,0) -> 0 | AA13: =ROUND(O13/$J$3*(Y13+_xlfn.XLOOKUP(C13,[1]Timesheet!B:B,[1]Timesheet!BS:BS,0)),0) -> 0 | AB13: =ROUND(IF(Y13>=8,P13,(P13/$J$3)*(Y13+_xlfn.XLOOKUP(C13,[1]Timesheet!B:B,[1]Timesheet!BS:BS,0))),0) -> 0 | AC13: =ROUND(IF(Y13>=14,Q13,(Q13/2)),0) -> 0 | AD13: =IF(_xlfn.XLOOKUP(Salary!C13,[1]Bus!B:B,[1]Bus!G:G,"",,-1)=1,0,ROUND((R13/$J$3)*ROUND(Y13+_xlfn.XLOOKUP(C13,[1]Timesheet!B:B,[1]Timesheet!BS:BS,0,,-1),0),0)) -> 0 | AE13: =IF(Y13>0,S13,0) -> 0 | AF13: =ROUND(IF(Y13>=8,T13,(T13/$J$3)*(Y13+_xlfn.XLOOKUP(C13,[1]Timesheet!B:B,[1]Timesheet!BS:BS,0))),0) -> 0 | AG13: =ROUND(IF(Y13>=8,U13,(U13/$J$3)*(Y13+_xlfn.XLOOKUP(C13,[1]Timesheet!B:B,[1]Timesheet!BS:BS,0))),0) -> 0 | AH13: =ROUND(IF(OR(CR13>0,Y13<8),(V13/$J$3)*(Y13+_xlfn.XLOOKUP(C13,[1]Timesheet!B:B,[1]Timesheet!BS:BS,0)),V13),0) -> 0 | AI13: =ROUND(IF(DAY(CR13)=26,IF(Y13=0,0,IF(W13=0,0,IF(OR(-(DK13)>DJ13,-(DK13)=DJ13),0,DJ13+DK13+DS13))),IF(CR13>0,0,IF(Y13=0,0,IF(W13=0,0,IF(OR(-(DK13)>DJ13,-(DK13)=DJ13),0,DJ13+DK13+DS13))))),0) -> 0 | AJ13: =IF(Y13>0,ROUND(IF(LEN(CR13)>2,(X13/$J$3)*(Y13+_xlfn.XLOOKUP(C13,[1]Timesheet!B:B,[1]Timesheet!BS:BS,0)),X13),0),0) -> 0 | AK13: =_xlfn.XLOOKUP(C13,[1]Overtime!$B$7:$B$557,[1]Overtime!$AN$7:$AN$557,0) -> 0 | AL13: =ROUND(((SUM(N13:P13)+SUM(T13:X13))/($J$3*8))*_xlfn.XLOOKUP(C13,[1]Overtime!$B$9:$B$557,[1]Overtime!$AU$9:$AU$557,0),0) -> 0 | AM13: =ROUND(((SUM(N13:P13)+SUM(T13:X13))/($J$3*8))*_xlfn.XLOOKUP(C13,[1]Overtime!$B$9:$B$557,[1]Overtime!$AY$9:$AY$557,0),0) -> 0 | AN13: =ROUND(AM13+AL13,0) -> 0 | AR13: =ROUND(_xlfn.XLOOKUP(C13,[1]Timesheet!$B$9:$B$458,[1]Timesheet!$BQ$9:$BQ$458,,,-1)*SUM(Salary!N13:P13,Salary!T13:X13)*20%/Salary!$J$3,0) -> 0 | AS13: 20000 | AT13: 0 | AV13: =IF(CV13="x",IF(IF(CR13>0,$CW$3-_xlfn.XLOOKUP(C13,[1]Timesheet!B:B,[1]Timesheet!BW:BW,0,,-1),$CW$3-_xlfn.XLOOKUP(C13,[1]Timesheet!B:B,[1]Timesheet!BW:BW,0,,-1)-$EB$3)<14,ROUND(L13*20.5%+M13*1%,0),0),0) -> 0 | AW13: =CK13 -> 0 | AX13: =CM13 -> 140625 | AZ13: 0 | BE13: =ROUND(SUM(Z13:AJ13)+AN13+AX13+AT13+AO13+AR13+AS13+AW13+AY13+AV13+AP13+AU13+AQ13+AZ13+BA13,0) -> 160625 | BF13: =IF(OR(CW13="x",CR13>0),0,15500000) -> 0 | BG13: 0 | BI13: =IF(CV13="x",0,ROUND(L13*1.5%,0)) -> 97500 | BJ13: =IF(CV13="x",0,ROUND(IF(BH13>0,M13*1%,0),0)) -> 0 | BK13: =IF(CV13="x",0,ROUND(IF(BH13>0,38948,0),0)) -> 0 | BL13: =ROUND(IF(AC13>0,IF(ROUND((BE13+CX13+CY13-AE13-AN13-AW13-AC13)*15%,0)>AC13,BE13+CX13+CY13-AE13-AN13-AW13,BE13+CX13+CY13-AE13-AN13-AW13-AC13+ROUND((BE13+CX13+CY13-AE13-AN13-AW13-AC13)*15%,0)),BE13+CX13+CY13-AE13-AN13-AW13),0) -> 160625 | BM13: =IF(OR(CW13="x",CR13>0),BL13,IF(BL13-BF13-BG13-SUM(BH13:BJ13)>0,BL13-BF13-BG13-SUM(BH13:BJ13),0)) -> 160625 | BN13: =IF(OR(CW13="x",CR13>0),ROUND(IF(BM13>4999999,BM13*10%,0),0),ROUND(IF(BM13>100000000,((BM13-100000000)*0.35+20500000),IF(AND(BM13>60000000,BM13<=100000000),((BM13-60000000)*0.3+8500000),IF(AND(BM13>30000000,BM13<=60000000),((BM13-30000000)*0.2+2500000),IF(AND(BM13>10000000,BM13<=30000000),((BM13-10000000)*0.1+500000),IF(BM13<0,0,(BM13*0.05)))))),0)) -> 0 | BO13: =SUM(BH13:BK13,BN13) -> 97500 | BP13: =IF(CV13="x",0,ROUND(IF(BH13>0,L13*17.5%,0),0)) -> 0 | BQ13: =IF(CV13="x",0,ROUND(IF(BI13>0,L13*3%,0),0)) -> 195000 | BR13: =IF(CV13="x",0,ROUND(IF(BJ13>0,M13*1%,0),0)) -> 0 | BS13: =IF(CV13="x",0,ROUND(IF(BK13>0,L13*2%,0),0)) -> 0 | BW13: 0 | CG13: =ROUND(BE13-BO13+BZ13-BT13-BU13-BX13-BV13+BW13+BY13+CA13-CB13,0) -> 63125 | CH13: =CG13+BN13+SUM(BH13:BK13)+SUM(BP13:BS13) -> 355625 | CI13: =IF(BH13=0,0,ROUND((SUM(N13:X13)-(R13+S13))/12,0)) -> 0 | CJ13: 0 | CK13: =ROUND((M13/$CK$3*CJ13),0) -> 0 | CL13: =3*1.5 -> 4.5 | CM13: =ROUND((M13/$J$3/8*CL13),0) -> 140625 | CO13: =CK13+CM13 -> 140625 | CP13: 46133 | CQ13: 46163 | CR13: 46207 | CS13: 0 | CT13: 0 | DC13: =_xlfn.XLOOKUP(C13,[1]Overtime!$B$8:$B$2327,[1]Overtime!$BA$8:$BA$2327,"",,-1) -> 0 | DD13: =_xlfn.XLOOKUP(C13,[1]Timesheet!$B$9:$B$2328,[1]Timesheet!$BS$9:$BS$2328,0,,-1) -> 0 | DE13: =_xlfn.XLOOKUP(C13,[1]Timesheet!$B$7:$B$616,[1]Timesheet!$BK$7:$BK$616,0)+_xlfn.XLOOKUP(C13,[1]Timesheet!$B$7:$B$616,[1]Timesheet!$AV$7:$AV$616,0)-_xlfn.XLOOKUP(C13,[1]Timesheet!$B$7:$B$616,[1]Timesheet!$AX$7:$AX$616,0)+_xlfn.XLOOKUP(C13,[1]Timesheet!$B$7:$B$616,[1]Timesheet!$AW$7:$AW$616,0)-_xlfn.XLOOKUP(C13,[1]Timesheet!$B$7:$B$616,[1]Timesheet!$AY$7:$AY$616,0) -> 0 | DF13: =DE13*(-100000) -> 0 | DG13: =_xlfn.XLOOKUP(C13,[1]Timesheet!$B$7:$B$616,[1]Timesheet!$BV$7:$BV$616,0)+_xlfn.XLOOKUP(C13,[1]Timesheet!$B$7:$B$616,[1]Timesheet!$AX$7:$AX$616,0)++_xlfn.XLOOKUP(C13,[1]Timesheet!$B$7:$B$616,[1]Timesheet!$AY$7:$AY$616,0) -> 7 | DH13: =IF(DG13>2,-1000000,IF(DG13=2,-500000,IF(DG13=1,-200000,0))) -> -1000000 | DI13: =_xlfn.XLOOKUP(C13,[1]Timesheet!$B$7:$B$616,[1]Timesheet!$AZ$7:$AZ$616,0)+_xlfn.XLOOKUP(C13,[1]Timesheet!$B$7:$B$616,[1]Timesheet!$BA$7:$BA$616,0) -> 0 | DJ13: =IF(CW13="x",IF((ROUND(Y13*W13/$J$3,0))<0,0,ROUND(Y13*W13/$J$3,0)),IF(OR(CR13>0,CS13>0,CT13>0),W13/$J$3*(Y13+_xlfn.XLOOKUP(C13,[1]Timesheet!B:B,[1]Timesheet!BS:BS,0,,-1)+_xlfn.XLOOKUP(C13,[1]Timesheet!B:B,[1]Timesheet!BU:BU,0,,-1)),IF(OR(DH13<0,DF13<0),IF(DI13>0,W13/$J$3*($J$3-DI13),W13),W13/$J$3*(Y13+_xlfn.XLOOKUP(C13,[1]Timesheet!B:B,[1]Timesheet!BS:BS,0,,-1)+_xlfn.XLOOKUP(C13,[1]Timesheet!B:B,[1]Timesheet!BU:BU,0,,-1))))) -> 0 | DK13: =DF13+DH13 -> -1000000 | DL13: =_xlfn.XLOOKUP(C13,[1]Timesheet!$B$7:$B$565,[1]Timesheet!$BB$7:$BB$565,0) -> 0 | DM13: =_xlfn.XLOOKUP(C13,[1]Timesheet!$B$7:$B$565,[1]Timesheet!$BC$7:$BC$565,0) -> 0 | DN13: =_xlfn.XLOOKUP(C13,[1]Timesheet!$B$7:$B$565,[1]Timesheet!$BF$7:$BF$565,0) -> 0 | DO13: =_xlfn.XLOOKUP(C13,[1]Timesheet!$B$7:$B$565,[1]Timesheet!$BJ$7:$BJ$565,0) -> 3 | DP13: =DN13+DO13 -> 3 | DQ13: =_xlfn.XLOOKUP(C13,[1]Timesheet!$B$7:$B$565,[1]Timesheet!$BT$7:$BT$565,0) -> 21 | DR13: =_xlfn.XLOOKUP(C13,[1]Timesheet!$B$7:$B$565,[1]Timesheet!$BM$7:$BM$565,0) -> 0 | DS13: =W13/$J$3*DR13 -> 0 | DT13: =ROUND(IF(BH13>0,L13*$DT$7,0),0) -> 0 | DU13: =ROUND(IF(BI13>0,L13*$DU$7,0),0) -> 195000 | DV13: =ROUND(IF(BJ13>0,M13*$DV$7,0),0) -> 0 | DW13: =ROUND(IF(BK13>0,L13*$DW$7,0),0) -> 0 | DX13: =SUM(N13:X13) -> 6800000 | DY13: =SUM(O13:S13) -> 600000 | DZ13: =SUM(W13:X13) -> 1000000 | EA13: =_xlfn.XLOOKUP(C13,[1]Timesheet!$B$7:$B$565,[1]Timesheet!$BI$7:$BI$565,0) -> 7 | EB13: =IF(AC13>0,ROUND((BE13+CX13+CY13-AE13-AN13-AW13-AC13)*15%,0),0) -> 0 | EC13: =AC13 -> 0 | ED13: =EB13-EC13 -> 0 | EE13: =BE13+CX13+CY13-AE13-AN13-AW13-BL13 -> 0 | EF13: =ROUND((SUM(N13:P13)+W13+X13+T13+U13+V13)/($J$3*8)*_xlfn.XLOOKUP(C13,[1]Overtime!$B$9:$B$557,[1]Overtime!$AU$9:$AU$557,0),0) -> 0 | EG13: =ROUND(((SUM(N13:P13)+W13+X13+T13+U13+V13)/($J$3*8))*_xlfn.XLOOKUP(C13,[1]Overtime!$B$9:$B$557,[1]Overtime!$AY$9:$AY$557,0),0) -> 0 | EH13: =ROUND(EG13+EF13,0) -> 0 | EI13: =AL13-EF13 -> 0 | EJ13: =AM13-EG13 -> 0 | EK13: =ROUND((SUM(N13:P13)+W13+X13+T13+U13+V13)/($J$3*8)*_xlfn.XLOOKUP(C13,[1]Overtime!$B$9:$B$557,[1]Overtime!$AO$9:$AO$557,0)*1.5,0) -> 0 | EL13: =ROUND((SUM(N13:P13)+W13+X13+T13+U13+V13)/($J$3*8)*_xlfn.XLOOKUP(C13,[1]Overtime!$B$9:$B$557,[1]Overtime!$AP$9:$AP$557,0)*2,0) -> 0 | EM13: =AN13-EK13-EL13 -> 0 | EN13: =ROUND(Y13*W13/$J$3,0) -> 0 | EO13: =DJ13-EN13 -> 0 | EP13: =IF(AI13=0,0,AI13-DK13-EN13) -> 0 | EQ13: 0 | ER13: =EQ13/4400000 -> 0
B14: =B13+1 -> 5 | C14: TIQN-2181 | D14: Ngô Minh Vinh | E14: =IF(CW14="x","Probation",IF(CR14>0,"Resigned - Official","Official")) -> Probation | F14: =IF(H14="management","6421.11",0) -> 0 | G14: Preparation | H14: Indirect | I14: 2nd Process | J14: Preparation | K14: Supporting worker | L14: =M14 -> 6700000 | M14: =N14+O14+P14+W14+X14+T14+U14+V14 -> 6700000 | N14: 5400000 | O14: 300000 | P14: 0 | Q14: 0 | R14: 300000 | S14: 0 | T14: 0 | U14: 0 | V14: 0 | W14: 1000000 | X14: 0 | Y14: =_xlfn.XLOOKUP(C14,[1]Timesheet!$B$9:$B$25,[1]Timesheet!$AO$9:$AO$25,0,,1) -> 0.5 | Z14: =ROUND(N14/$J$3*Y14,0) -> 103846 | AA14: =ROUND(O14/$J$3*(Y14+_xlfn.XLOOKUP(C14,[1]Timesheet!B:B,[1]Timesheet!BS:BS,0)),0) -> 5769 | AB14: =ROUND(IF(Y14>=8,P14,(P14/$J$3)*(Y14+_xlfn.XLOOKUP(C14,[1]Timesheet!B:B,[1]Timesheet!BS:BS,0))),0) -> 0 | AC14: =ROUND(IF(Y14>=14,Q14,(Q14/2)),0) -> 0 | AD14: =IF(_xlfn.XLOOKUP(Salary!C14,[1]Bus!B:B,[1]Bus!G:G,"",,-1)=1,0,ROUND((R14/$J$3)*ROUND(Y14+_xlfn.XLOOKUP(C14,[1]Timesheet!B:B,[1]Timesheet!BS:BS,0,,-1),0),0)) -> 11538 | AE14: =IF(Y14>0,S14,0) -> 0 | AF14: =ROUND(IF(Y14>=8,T14,(T14/$J$3)*(Y14+_xlfn.XLOOKUP(C14,[1]Timesheet!B:B,[1]Timesheet!BS:BS,0))),0) -> 0 | AG14: =ROUND(IF(Y14>=8,U14,(U14/$J$3)*(Y14+_xlfn.XLOOKUP(C14,[1]Timesheet!B:B,[1]Timesheet!BS:BS,0))),0) -> 0 | AH14: =ROUND(IF(OR(CR14>0,Y14<8),(V14/$J$3)*(Y14+_xlfn.XLOOKUP(C14,[1]Timesheet!B:B,[1]Timesheet!BS:BS,0)),V14),0) -> 0 | AI14: =ROUND(IF(DAY(CR14)=26,IF(Y14=0,0,IF(W14=0,0,IF(OR(-(DK14)>DJ14,-(DK14)=DJ14),0,DJ14+DK14+DS14))),IF(CR14>0,0,IF(Y14=0,0,IF(W14=0,0,IF(OR(-(DK14)>DJ14,-(DK14)=DJ14),0,DJ14+DK14+DS14))))),0) -> 0 | AJ14: =IF(Y14>0,ROUND(IF(LEN(CR14)>2,(X14/$J$3)*(Y14+_xlfn.XLOOKUP(C14,[1]Timesheet!B:B,[1]Timesheet!BS:BS,0)),X14),0),0) -> 0 | AK14: =_xlfn.XLOOKUP(C14,[1]Overtime!$B$7:$B$557,[1]Overtime!$AN$7:$AN$557,0) -> 0 | AL14: =ROUND(((SUM(N14:P14)+SUM(T14:X14))/($J$3*8))*_xlfn.XLOOKUP(C14,[1]Overtime!$B$9:$B$557,[1]Overtime!$AU$9:$AU$557,0),0) -> 0 | AM14: =ROUND(((SUM(N14:P14)+SUM(T14:X14))/($J$3*8))*_xlfn.XLOOKUP(C14,[1]Overtime!$B$9:$B$557,[1]Overtime!$AY$9:$AY$557,0),0) -> 0 | AN14: =ROUND(AM14+AL14,0) -> 0 | AR14: =ROUND(_xlfn.XLOOKUP(C14,[1]Timesheet!$B$9:$B$458,[1]Timesheet!$BQ$9:$BQ$458,,,-1)*SUM(Salary!N14:P14,Salary!T14:X14)*20%/Salary!$J$3,0) -> 0 | AS14: 0 | AT14: 0 | AV14: =IF(CV14="x",IF(IF(CR14>0,$CW$3-_xlfn.XLOOKUP(C14,[1]Timesheet!B:B,[1]Timesheet!BW:BW,0,,-1),$CW$3-_xlfn.XLOOKUP(C14,[1]Timesheet!B:B,[1]Timesheet!BW:BW,0,,-1)-$EB$3)<14,ROUND(L14*20.5%+M14*1%,0),0),0) -> 0 | AW14: =CK14 -> 0 | AX14: =CM14 -> 0 | AZ14: 0 | BE14: =ROUND(SUM(Z14:AJ14)+AN14+AX14+AT14+AO14+AR14+AS14+AW14+AY14+AV14+AP14+AU14+AQ14+AZ14+BA14,0) -> 121153 | BF14: =IF(OR(CW14="x",CR14>0),0,15500000) -> 0 | BG14: 0 | BJ14: =IF(CV14="x",0,ROUND(IF(BH14>0,M14*1%,0),0)) -> 0 | BK14: =IF(CV14="x",0,ROUND(IF(BH14>0,38948,0),0)) -> 0 | BL14: =ROUND(IF(AC14>0,IF(ROUND((BE14+CX14+CY14-AE14-AN14-AW14-AC14)*15%,0)>AC14,BE14+CX14+CY14-AE14-AN14-AW14,BE14+CX14+CY14-AE14-AN14-AW14-AC14+ROUND((BE14+CX14+CY14-AE14-AN14-AW14-AC14)*15%,0)),BE14+CX14+CY14-AE14-AN14-AW14),0) -> 121153 | BM14: =IF(OR(CW14="x",CR14>0),BL14,IF(BL14-BF14-BG14-SUM(BH14:BJ14)>0,BL14-BF14-BG14-SUM(BH14:BJ14),0)) -> 121153 | BN14: =IF(OR(CW14="x",CR14>0),ROUND(IF(BM14>4999999,BM14*10%,0),0),ROUND(IF(BM14>100000000,((BM14-100000000)*0.35+20500000),IF(AND(BM14>60000000,BM14<=100000000),((BM14-60000000)*0.3+8500000),IF(AND(BM14>30000000,BM14<=60000000),((BM14-30000000)*0.2+2500000),IF(AND(BM14>10000000,BM14<=30000000),((BM14-10000000)*0.1+500000),IF(BM14<0,0,(BM14*0.05)))))),0)) -> 0 | BO14: =SUM(BH14:BK14,BN14) -> 0 | BP14: =IF(CV14="x",0,ROUND(IF(BH14>0,L14*17.5%,0),0)) -> 0 | BQ14: =IF(CV14="x",0,ROUND(IF(BI14>0,L14*3%,0),0)) -> 0 | BR14: =IF(CV14="x",0,ROUND(IF(BJ14>0,M14*1%,0),0)) -> 0 | BS14: =IF(CV14="x",0,ROUND(IF(BK14>0,L14*2%,0),0)) -> 0 | BW14: 0 | CG14: =ROUND(BE14-BO14+BZ14-BT14-BU14-BX14-BV14+BW14+BY14+CA14-CB14,0) -> 121153 | CH14: =CG14+BN14+SUM(BH14:BK14)+SUM(BP14:BS14) -> 121153 | CI14: =IF(BH14=0,0,ROUND((SUM(N14:X14)-(R14+S14))/12,0)) -> 0 | CK14: =ROUND((M14/$CK$3*CJ14),0) -> 0 | CM14: =ROUND((M14/$J$3/8*CL14),0) -> 0 | CO14: =CK14+CM14 -> 0 | CP14: 46178 | CQ14: 46208 | CR14: 46202 | CS14: 0 | CT14: 0 | CV14: x | CW14: x | DC14: =_xlfn.XLOOKUP(C14,[1]Overtime!$B$8:$B$2327,[1]Overtime!$BA$8:$BA$2327,"",,-1) -> 0 | DD14: =_xlfn.XLOOKUP(C14,[1]Timesheet!$B$9:$B$2328,[1]Timesheet!$BS$9:$BS$2328,0,,-1) -> 0 | DE14: =_xlfn.XLOOKUP(C14,[1]Timesheet!$B$7:$B$616,[1]Timesheet!$BK$7:$BK$616,0)+_xlfn.XLOOKUP(C14,[1]Timesheet!$B$7:$B$616,[1]Timesheet!$AV$7:$AV$616,0)-_xlfn.XLOOKUP(C14,[1]Timesheet!$B$7:$B$616,[1]Timesheet!$AX$7:$AX$616,0)+_xlfn.XLOOKUP(C14,[1]Timesheet!$B$7:$B$616,[1]Timesheet!$AW$7:$AW$616,0)-_xlfn.XLOOKUP(C14,[1]Timesheet!$B$7:$B$616,[1]Timesheet!$AY$7:$AY$616,0) -> 1 | DF14: =DE14*(-100000) -> -100000 | DG14: =_xlfn.XLOOKUP(C14,[1]Timesheet!$B$7:$B$616,[1]Timesheet!$BV$7:$BV$616,0)+_xlfn.XLOOKUP(C14,[1]Timesheet!$B$7:$B$616,[1]Timesheet!$AX$7:$AX$616,0)++_xlfn.XLOOKUP(C14,[1]Timesheet!$B$7:$B$616,[1]Timesheet!$AY$7:$AY$616,0) -> 1 | DH14: =IF(DG14>2,-1000000,IF(DG14=2,-500000,IF(DG14=1,-200000,0))) -> -200000 | DI14: =_xlfn.XLOOKUP(C14,[1]Timesheet!$B$7:$B$616,[1]Timesheet!$AZ$7:$AZ$616,0)+_xlfn.XLOOKUP(C14,[1]Timesheet!$B$7:$B$616,[1]Timesheet!$BA$7:$BA$616,0) -> 0 | DJ14: =IF(CW14="x",IF((ROUND(Y14*W14/$J$3,0))<0,0,ROUND(Y14*W14/$J$3,0)),IF(OR(CR14>0,CS14>0,CT14>0),W14/$J$3*(Y14+_xlfn.XLOOKUP(C14,[1]Timesheet!B:B,[1]Timesheet!BS:BS,0,,-1)+_xlfn.XLOOKUP(C14,[1]Timesheet!B:B,[1]Timesheet!BU:BU,0,,-1)),IF(OR(DH14<0,DF14<0),IF(DI14>0,W14/$J$3*($J$3-DI14),W14),W14/$J$3*(Y14+_xlfn.XLOOKUP(C14,[1]Timesheet!B:B,[1]Timesheet!BS:BS,0,,-1)+_xlfn.XLOOKUP(C14,[1]Timesheet!B:B,[1]Timesheet!BU:BU,0,,-1))))) -> 19231 | DK14: =DF14+DH14 -> -300000 | DL14: =_xlfn.XLOOKUP(C14,[1]Timesheet!$B$7:$B$565,[1]Timesheet!$BB$7:$BB$565,0) -> 0 | DM14: =_xlfn.XLOOKUP(C14,[1]Timesheet!$B$7:$B$565,[1]Timesheet!$BC$7:$BC$565,0) -> 0 | DN14: =_xlfn.XLOOKUP(C14,[1]Timesheet!$B$7:$B$565,[1]Timesheet!$BF$7:$BF$565,0) -> 0 | DO14: =_xlfn.XLOOKUP(C14,[1]Timesheet!$B$7:$B$565,[1]Timesheet!$BJ$7:$BJ$565,0) -> 0 | DP14: =DN14+DO14 -> 0 | DQ14: =_xlfn.XLOOKUP(C14,[1]Timesheet!$B$7:$B$565,[1]Timesheet!$BT$7:$BT$565,0) -> 21 | DR14: =_xlfn.XLOOKUP(C14,[1]Timesheet!$B$7:$B$565,[1]Timesheet!$BM$7:$BM$565,0) -> 0 | DS14: =W14/$J$3*DR14 -> 0 | DT14: =ROUND(IF(BH14>0,L14*$DT$7,0),0) -> 0 | DU14: =ROUND(IF(BI14>0,L14*$DU$7,0),0) -> 0 | DV14: =ROUND(IF(BJ14>0,M14*$DV$7,0),0) -> 0 | DW14: =ROUND(IF(BK14>0,L14*$DW$7,0),0) -> 0 | DX14: =SUM(N14:X14) -> 7000000 | DY14: =SUM(O14:S14) -> 600000 | DZ14: =SUM(W14:X14) -> 1000000 | EA14: =_xlfn.XLOOKUP(C14,[1]Timesheet!$B$7:$B$565,[1]Timesheet!$BI$7:$BI$565,0) -> 1 | EB14: =IF(AC14>0,ROUND((BE14+CX14+CY14-AE14-AN14-AW14-AC14)*15%,0),0) -> 0 | EC14: =AC14 -> 0 | ED14: =EB14-EC14 -> 0 | EE14: =BE14+CX14+CY14-AE14-AN14-AW14-BL14 -> 0 | EF14: =ROUND((SUM(N14:P14)+W14+X14+T14+U14+V14)/($J$3*8)*_xlfn.XLOOKUP(C14,[1]Overtime!$B$9:$B$557,[1]Overtime!$AU$9:$AU$557,0),0) -> 0 | EG14: =ROUND(((SUM(N14:P14)+W14+X14+T14+U14+V14)/($J$3*8))*_xlfn.XLOOKUP(C14,[1]Overtime!$B$9:$B$557,[1]Overtime!$AY$9:$AY$557,0),0) -> 0 | EH14: =ROUND(EG14+EF14,0) -> 0 | EI14: =AL14-EF14 -> 0 | EJ14: =AM14-EG14 -> 0 | EK14: =ROUND((SUM(N14:P14)+W14+X14+T14+U14+V14)/($J$3*8)*_xlfn.XLOOKUP(C14,[1]Overtime!$B$9:$B$557,[1]Overtime!$AO$9:$AO$557,0)*1.5,0) -> 0 | EL14: =ROUND((SUM(N14:P14)+W14+X14+T14+U14+V14)/($J$3*8)*_xlfn.XLOOKUP(C14,[1]Overtime!$B$9:$B$557,[1]Overtime!$AP$9:$AP$557,0)*2,0) -> 0 | EM14: =AN14-EK14-EL14 -> 0 | EN14: =ROUND(Y14*W14/$J$3,0) -> 19231 | EO14: =DJ14-EN14 -> 0 | EP14: =IF(AI14=0,0,AI14-DK14-EN14) -> 0 | EQ14: 0 | ER14: =EQ14/4400000 -> 0
B15: =B14+1 -> 6 | C15: TIQN-2192 | D15: Nguyễn Thị Hiền | E15: =IF(CW15="x","Probation",IF(CR15>0,"Resigned - Official","Official")) -> Probation | F15: =IF(H15="management","6421.11",0) -> 0 | G15: Sewing | H15: Direct | I15: Supporting line | J15: Sewing | K15: Supporting worker | L15: =M15 -> 6300000 | M15: =N15+O15+P15+W15+X15+T15+U15+V15 -> 6300000 | N15: 5200000 | O15: 100000 | P15: 0 | Q15: 0 | R15: 300000 | S15: 0 | T15: 0 | U15: 0 | V15: 0 | W15: 1000000 | X15: 0 | Y15: =_xlfn.XLOOKUP(C15,[1]Timesheet!$B$9:$B$25,[1]Timesheet!$AO$9:$AO$25,0,,1) -> 0 | Z15: =ROUND(N15/$J$3*Y15,0) -> 0 | AA15: =ROUND(O15/$J$3*(Y15+_xlfn.XLOOKUP(C15,[1]Timesheet!B:B,[1]Timesheet!BS:BS,0)),0) -> 0 | AB15: =ROUND(IF(Y15>=8,P15,(P15/$J$3)*(Y15+_xlfn.XLOOKUP(C15,[1]Timesheet!B:B,[1]Timesheet!BS:BS,0))),0) -> 0 | AC15: =ROUND(IF(Y15>=14,Q15,(Q15/2)),0) -> 0 | AD15: =IF(_xlfn.XLOOKUP(Salary!C15,[1]Bus!B:B,[1]Bus!G:G,"",,-1)=1,0,ROUND((R15/$J$3)*ROUND(Y15+_xlfn.XLOOKUP(C15,[1]Timesheet!B:B,[1]Timesheet!BS:BS,0,,-1),0),0)) -> 0 | AE15: =IF(Y15>0,S15,0) -> 0 | AF15: =ROUND(IF(Y15>=8,T15,(T15/$J$3)*(Y15+_xlfn.XLOOKUP(C15,[1]Timesheet!B:B,[1]Timesheet!BS:BS,0))),0) -> 0 | AG15: =ROUND(IF(Y15>=8,U15,(U15/$J$3)*(Y15+_xlfn.XLOOKUP(C15,[1]Timesheet!B:B,[1]Timesheet!BS:BS,0))),0) -> 0 | AH15: =ROUND(IF(OR(CR15>0,Y15<8),(V15/$J$3)*(Y15+_xlfn.XLOOKUP(C15,[1]Timesheet!B:B,[1]Timesheet!BS:BS,0)),V15),0) -> 0 | AI15: =ROUND(IF(DAY(CR15)=26,IF(Y15=0,0,IF(W15=0,0,IF(OR(-(DK15)>DJ15,-(DK15)=DJ15),0,DJ15+DK15+DS15))),IF(CR15>0,0,IF(Y15=0,0,IF(W15=0,0,IF(OR(-(DK15)>DJ15,-(DK15)=DJ15),0,DJ15+DK15+DS15))))),0) -> 0 | AJ15: =IF(Y15>0,ROUND(IF(LEN(CR15)>2,(X15/$J$3)*(Y15+_xlfn.XLOOKUP(C15,[1]Timesheet!B:B,[1]Timesheet!BS:BS,0)),X15),0),0) -> 0 | AK15: =_xlfn.XLOOKUP(C15,[1]Overtime!$B$7:$B$557,[1]Overtime!$AN$7:$AN$557,0) -> 0 | AL15: =ROUND(((SUM(N15:P15)+SUM(T15:X15))/($J$3*8))*_xlfn.XLOOKUP(C15,[1]Overtime!$B$9:$B$557,[1]Overtime!$AU$9:$AU$557,0),0) -> 0 | AM15: =ROUND(((SUM(N15:P15)+SUM(T15:X15))/($J$3*8))*_xlfn.XLOOKUP(C15,[1]Overtime!$B$9:$B$557,[1]Overtime!$AY$9:$AY$557,0),0) -> 0 | AN15: =ROUND(AM15+AL15,0) -> 0 | AR15: =ROUND(_xlfn.XLOOKUP(C15,[1]Timesheet!$B$9:$B$458,[1]Timesheet!$BQ$9:$BQ$458,,,-1)*SUM(Salary!N15:P15,Salary!T15:X15)*20%/Salary!$J$3,0) -> 0 | AS15: 20000 | AT15: 0 | AV15: =IF(CV15="x",IF(IF(CR15>0,$CW$3-_xlfn.XLOOKUP(C15,[1]Timesheet!B:B,[1]Timesheet!BW:BW,0,,-1),$CW$3-_xlfn.XLOOKUP(C15,[1]Timesheet!B:B,[1]Timesheet!BW:BW,0,,-1)-$EB$3)<14,ROUND(L15*20.5%+M15*1%,0),0),0) -> 0 | AW15: =CK15 -> 0 | AX15: =CM15 -> 45433 | AZ15: 0 | BE15: =ROUND(SUM(Z15:AJ15)+AN15+AX15+AT15+AO15+AR15+AS15+AW15+AY15+AV15+AP15+AU15+AQ15+AZ15+BA15,0) -> 65433 | BF15: =IF(OR(CW15="x",CR15>0),0,15500000) -> 0 | BG15: 0 | BJ15: =IF(CV15="x",0,ROUND(IF(BH15>0,M15*1%,0),0)) -> 0 | BK15: =IF(CV15="x",0,ROUND(IF(BH15>0,38948,0),0)) -> 0 | BL15: =ROUND(IF(AC15>0,IF(ROUND((BE15+CX15+CY15-AE15-AN15-AW15-AC15)*15%,0)>AC15,BE15+CX15+CY15-AE15-AN15-AW15,BE15+CX15+CY15-AE15-AN15-AW15-AC15+ROUND((BE15+CX15+CY15-AE15-AN15-AW15-AC15)*15%,0)),BE15+CX15+CY15-AE15-AN15-AW15),0) -> 65433 | BM15: =IF(OR(CW15="x",CR15>0),BL15,IF(BL15-BF15-BG15-SUM(BH15:BJ15)>0,BL15-BF15-BG15-SUM(BH15:BJ15),0)) -> 65433 | BN15: =IF(OR(CW15="x",CR15>0),ROUND(IF(BM15>4999999,BM15*10%,0),0),ROUND(IF(BM15>100000000,((BM15-100000000)*0.35+20500000),IF(AND(BM15>60000000,BM15<=100000000),((BM15-60000000)*0.3+8500000),IF(AND(BM15>30000000,BM15<=60000000),((BM15-30000000)*0.2+2500000),IF(AND(BM15>10000000,BM15<=30000000),((BM15-10000000)*0.1+500000),IF(BM15<0,0,(BM15*0.05)))))),0)) -> 0 | BO15: =SUM(BH15:BK15,BN15) -> 0 | BP15: =IF(CV15="x",0,ROUND(IF(BH15>0,L15*17.5%,0),0)) -> 0 | BQ15: =IF(CV15="x",0,ROUND(IF(BI15>0,L15*3%,0),0)) -> 0 | BR15: =IF(CV15="x",0,ROUND(IF(BJ15>0,M15*1%,0),0)) -> 0 | BS15: =IF(CV15="x",0,ROUND(IF(BK15>0,L15*2%,0),0)) -> 0 | BW15: 0 | CG15: =ROUND(BE15-BO15+BZ15-BT15-BU15-BX15-BV15+BW15+BY15+CA15-CB15,0) -> 65433 | CH15: =CG15+BN15+SUM(BH15:BK15)+SUM(BP15:BS15) -> 65433 | CI15: =IF(BH15=0,0,ROUND((SUM(N15:X15)-(R15+S15))/12,0)) -> 0 | CK15: =ROUND((M15/$CK$3*CJ15),0) -> 0 | CL15: 1.5 | CM15: =ROUND((M15/$J$3/8*CL15),0) -> 45433 | CO15: =CK15+CM15 -> 45433 | CP15: 46182 | CQ15: 46212 | CR15: 46202 | CS15: 0 | CT15: 0 | CV15: x | CW15: x | DC15: =_xlfn.XLOOKUP(C15,[1]Overtime!$B$8:$B$2327,[1]Overtime!$BA$8:$BA$2327,"",,-1) -> 0 | DD15: =_xlfn.XLOOKUP(C15,[1]Timesheet!$B$9:$B$2328,[1]Timesheet!$BS$9:$BS$2328,0,,-1) -> 0 | DE15: =_xlfn.XLOOKUP(C15,[1]Timesheet!$B$7:$B$616,[1]Timesheet!$BK$7:$BK$616,0)+_xlfn.XLOOKUP(C15,[1]Timesheet!$B$7:$B$616,[1]Timesheet!$AV$7:$AV$616,0)-_xlfn.XLOOKUP(C15,[1]Timesheet!$B$7:$B$616,[1]Timesheet!$AX$7:$AX$616,0)+_xlfn.XLOOKUP(C15,[1]Timesheet!$B$7:$B$616,[1]Timesheet!$AW$7:$AW$616,0)-_xlfn.XLOOKUP(C15,[1]Timesheet!$B$7:$B$616,[1]Timesheet!$AY$7:$AY$616,0) -> 0 | DF15: =DE15*(-100000) -> 0 | DG15: =_xlfn.XLOOKUP(C15,[1]Timesheet!$B$7:$B$616,[1]Timesheet!$BV$7:$BV$616,0)+_xlfn.XLOOKUP(C15,[1]Timesheet!$B$7:$B$616,[1]Timesheet!$AX$7:$AX$616,0)++_xlfn.XLOOKUP(C15,[1]Timesheet!$B$7:$B$616,[1]Timesheet!$AY$7:$AY$616,0) -> 2 | DH15: =IF(DG15>2,-1000000,IF(DG15=2,-500000,IF(DG15=1,-200000,0))) -> -500000 | DI15: =_xlfn.XLOOKUP(C15,[1]Timesheet!$B$7:$B$616,[1]Timesheet!$AZ$7:$AZ$616,0)+_xlfn.XLOOKUP(C15,[1]Timesheet!$B$7:$B$616,[1]Timesheet!$BA$7:$BA$616,0) -> 0 | DJ15: =IF(CW15="x",IF((ROUND(Y15*W15/$J$3,0))<0,0,ROUND(Y15*W15/$J$3,0)),IF(OR(CR15>0,CS15>0,CT15>0),W15/$J$3*(Y15+_xlfn.XLOOKUP(C15,[1]Timesheet!B:B,[1]Timesheet!BS:BS,0,,-1)+_xlfn.XLOOKUP(C15,[1]Timesheet!B:B,[1]Timesheet!BU:BU,0,,-1)),IF(OR(DH15<0,DF15<0),IF(DI15>0,W15/$J$3*($J$3-DI15),W15),W15/$J$3*(Y15+_xlfn.XLOOKUP(C15,[1]Timesheet!B:B,[1]Timesheet!BS:BS,0,,-1)+_xlfn.XLOOKUP(C15,[1]Timesheet!B:B,[1]Timesheet!BU:BU,0,,-1))))) -> 0 | DK15: =DF15+DH15 -> -500000 | DL15: =_xlfn.XLOOKUP(C15,[1]Timesheet!$B$7:$B$565,[1]Timesheet!$BB$7:$BB$565,0) -> 0 | DM15: =_xlfn.XLOOKUP(C15,[1]Timesheet!$B$7:$B$565,[1]Timesheet!$BC$7:$BC$565,0) -> 0 | DN15: =_xlfn.XLOOKUP(C15,[1]Timesheet!$B$7:$B$565,[1]Timesheet!$BF$7:$BF$565,0) -> 0 | DO15: =_xlfn.XLOOKUP(C15,[1]Timesheet!$B$7:$B$565,[1]Timesheet!$BJ$7:$BJ$565,0) -> 0 | DP15: =DN15+DO15 -> 0 | DQ15: =_xlfn.XLOOKUP(C15,[1]Timesheet!$B$7:$B$565,[1]Timesheet!$BT$7:$BT$565,0) -> 21 | DR15: =_xlfn.XLOOKUP(C15,[1]Timesheet!$B$7:$B$565,[1]Timesheet!$BM$7:$BM$565,0) -> 0 | DS15: =W15/$J$3*DR15 -> 0 | DT15: =ROUND(IF(BH15>0,L15*$DT$7,0),0) -> 0 | DU15: =ROUND(IF(BI15>0,L15*$DU$7,0),0) -> 0 | DV15: =ROUND(IF(BJ15>0,M15*$DV$7,0),0) -> 0 | DW15: =ROUND(IF(BK15>0,L15*$DW$7,0),0) -> 0 | DX15: =SUM(N15:X15) -> 6600000 | DY15: =SUM(O15:S15) -> 400000 | DZ15: =SUM(W15:X15) -> 1000000 | EA15: =_xlfn.XLOOKUP(C15,[1]Timesheet!$B$7:$B$565,[1]Timesheet!$BI$7:$BI$565,0) -> 2 | EB15: =IF(AC15>0,ROUND((BE15+CX15+CY15-AE15-AN15-AW15-AC15)*15%,0),0) -> 0 | EC15: =AC15 -> 0 | ED15: =EB15-EC15 -> 0 | EE15: =BE15+CX15+CY15-AE15-AN15-AW15-BL15 -> 0 | EF15: =ROUND((SUM(N15:P15)+W15+X15+T15+U15+V15)/($J$3*8)*_xlfn.XLOOKUP(C15,[1]Overtime!$B$9:$B$557,[1]Overtime!$AU$9:$AU$557,0),0) -> 0 | EG15: =ROUND(((SUM(N15:P15)+W15+X15+T15+U15+V15)/($J$3*8))*_xlfn.XLOOKUP(C15,[1]Overtime!$B$9:$B$557,[1]Overtime!$AY$9:$AY$557,0),0) -> 0 | EH15: =ROUND(EG15+EF15,0) -> 0 | EI15: =AL15-EF15 -> 0 | EJ15: =AM15-EG15 -> 0 | EK15: =ROUND((SUM(N15:P15)+W15+X15+T15+U15+V15)/($J$3*8)*_xlfn.XLOOKUP(C15,[1]Overtime!$B$9:$B$557,[1]Overtime!$AO$9:$AO$557,0)*1.5,0) -> 0 | EL15: =ROUND((SUM(N15:P15)+W15+X15+T15+U15+V15)/($J$3*8)*_xlfn.XLOOKUP(C15,[1]Overtime!$B$9:$B$557,[1]Overtime!$AP$9:$AP$557,0)*2,0) -> 0 | EM15: =AN15-EK15-EL15 -> 0 | EN15: =ROUND(Y15*W15/$J$3,0) -> 0 | EO15: =DJ15-EN15 -> 0 | EP15: =IF(AI15=0,0,AI15-DK15-EN15) -> 0 | EQ15: 0 | ER15: =EQ15/4400000 -> 0
